<?xml version="1.0"?>

<robot name="vstone_sota">
    <material name="green">
        <color rgba="0 0.5 0 1" />
    </material>

    <material name="blue">
        <color rgba="0 0 0.5 1" />
    </material>

    <material name="grey">
        <color rgba="0.5 0.5 0.5 1" />
    </material>

    <link name="base_link">
        <visual>
            <geometry>
                <!-- cylinder radius=".150" length=".005" / --> 
                <mesh filename="file:///home/vboxuser/SotaObj/Body/s1201.obj" scale="0.001 0.001 0.001"/>
            </geometry>
            <origin xyz="0 0 .0025" rpy="1.57 0 0" />
            <material name="blue" />
        </visual>
    </link>

    <link name="body_link">
        <visual>
            <geometry>
                <mesh filename="file:///home/vboxuser/SotaObj/Body/SotaBody.obj" scale="0.001 0.001 0.001"/>
            </geometry>
            <origin xyz="0 0 0" rpy="1.57 0 0" />
            <material name="blue" />
        </visual>
    </link>

    <link name="head_link">
        <visual>
            <geometry>
                <!-- <mesh filename="file:///home/vboxuser/SotaObj/Head/s4301autosmooth.obj" scale="0.001 0.001 0.001"/>
                <mesh filename="file:///home/vboxuser/SotaObj/Head/s4302autosmooth.obj" scale="0.001 0.001 0.001"/>
                <mesh filename="file:///home/vboxuser/SotaObj/Head/s4303autosmooth.obj" scale="0.001 0.001 0.001"/>
                <mesh filename="file:///home/vboxuser/SotaObj/Head/s4304autosmooth.obj" scale="0.001 0.001 0.001"/>
                <mesh filename="file:///home/vboxuser/SotaObj/Head/s4306.obj" scale="0.001 0.001 0.001"/>
                <mesh filename="file:///home/vboxuser/SotaObj/Head/s4306m.obj" scale="0.001 0.001 0.001"/>  -->
                <mesh filename="file:///home/vboxuser/SotaObj/Head/SotaHead.obj" scale="0.001 0.001 0.001"/>
            </geometry>
            <origin xyz="0 0 -.19" rpy="1.57 0 0" />
            <material name="blue"/>
        </visual>
    </link>

    <link name="head_pitch_link">
    </link>

    <link name="head_roll_link">
    </link>

    <link name="head_yaw_link">
    </link>


    <link name="mouth_link">
        <visual>
            <geometry>
                <mesh filename="file:///home/vboxuser/SotaObj/Head/s4307.obj" scale="0.001 0.001 0.001"/>
            </geometry>
            <origin xyz="0 0 -.19" rpy="1.57 0 0" />
            <material name="blue"/>
        </visual>
    </link>

    <link name="left_eye_link">
        <visual>
            <geometry>
                <mesh filename="file:///home/vboxuser/SotaObj/Head/s4305.obj" scale="0.001 0.001 0.001"/>
            </geometry>
            <origin xyz="0 0 -.19" rpy="1.57 0 0" />
            <material name="blue"/>
        </visual>
    </link>

    <link name="right_eye_link">
        <visual>
            <geometry>
                <mesh filename="file:///home/vboxuser/SotaObj/Head/s4305m.obj" scale="0.001 0.001 0.001"/>
            </geometry>
            <origin xyz="0 0 -.19" rpy="1.57 0 0" />
            <material name="blue"/>
        </visual>
    </link>

    <link name="power_link">
        <visual>
            <geometry>
                <mesh filename="file:///home/vboxuser/SotaObj/Body/s9401.obj" scale="0.001 0.001 0.001"/>
            </geometry>
            <origin xyz="0 0 -.19" rpy="1.57 0 0" />
            <material name="blue"/>
        </visual>
    </link>

    <link name="volume_up_link">
        <visual>
            <geometry>
                <mesh filename="file:///home/vboxuser/SotaObj/Body/s9402R.obj" scale="0.001 0.001 0.001"/>
            </geometry>
            <origin xyz="0 0 -.19" rpy="1.57 0 0" />
            <material name="blue"/>
        </visual>
    </link>

        <link name="volume_down_link">
        <visual>
            <geometry>
                <mesh filename="file:///home/vboxuser/SotaObj/Body/s9402L.obj" scale="0.001 0.001 0.001"/>
            </geometry>
            <origin xyz="0 0 -.19" rpy="1.57 0 0" />
            <material name="blue"/>
        </visual>
    </link>


    <link name="left_shoulder_link">
        <visual>
            <geometry>
               <mesh filename="file:///home/vboxuser/SotaObj/LeftShoulder/s3101autosmooth.obj" scale="0.001 0.001 0.001"/>
            </geometry>
            <origin xyz="-.039 -.1415 0" rpy="0 0 0" />
            <material name="blue"/>
        </visual>
    </link>

    <link name="left_arm_link" >
            <visual>
            <geometry>
                <!-- <mesh filename="file:///home/vboxuser/SotaObj/LeftArm/s3202autosmooth.obj" scale="0.001 0.001 0.001"/>
                <mesh filename="file:///home/vboxuser/SotaObj/LeftArm/s3201.obj" scale="0.001 0.001 0.001"/> -->
                <mesh filename="file:///home/vboxuser/SotaObj/LeftArm/SotaLeftArm.obj" scale="0.001 0.001 0.001"/>

            </geometry>
            <origin xyz="-.0615 -.102528854 0" rpy="0 0 0" />

            <material name="blue"/>
        </visual>
    </link>
    

    <link name="right_shoulder_link">
        <visual>
            <geometry>
                <mesh filename="file:///home/vboxuser/SotaObj/RightShoulder/s3101mautosmooth.obj" scale="0.001 0.001 0.001"/>
            </geometry>
            <origin xyz=".039 -.1415 0" rpy="0 0 0" />
            <material name="blue"/>
        </visual>
    </link>

    <link name="right_arm_link" >
            <visual>
            <geometry>
               <!--  <mesh filename="file:///home/vboxuser/SotaObj/RightArm/s3201m.obj" scale="0.001 0.001 0.001"/>
                <mesh filename="file:///home/vboxuser/SotaObj/RightArm/s3102mautosmooth.obj" scale="0.001 0.001 0.001"/>  -->
                <mesh filename="file:///home/vboxuser/SotaObj/RightArm/SotaRightArm.obj" scale="0.001 0.001 0.001"/>
            </geometry>
            <origin xyz=".0615 -.102528854 0" rpy="0 0 0" />
            <material name="blue"/>
        </visual>
    </link>


    <joint name="base_body_joint" type="revolute">
        <parent link="base_link" />
        <child link="body_link" />
        <origin xyz="0 0 .005" />
        <axis xyz="0 0 1" />
        <limit lower="-1.077363736" upper="1.077363736" effort="100" velocity="100" />
    </joint>

    <joint name="body_head_yaw_joint" type="revolute">
        <parent link="body_link" />
        <child link="head_yaw_link" />
        <origin xyz="0 0 .190" rpy="0 0 0" />
        <axis xyz="0 0 1" />
        <limit lower="-1.495996502" upper="1.495996502" effort="100" velocity="100" />
    </joint>

    <joint name="head_yaw_roll_joint" type="revolute">
        <parent link="head_yaw_link" />
        <child link="head_roll_link" />
        <origin xyz="0 0 0" rpy="0 0 0" />
        <axis xyz="0 1 0" />
        <limit lower="-1.495996502" upper="1.495996502" effort="100" velocity="100" />
    </joint>
    
    <joint name="head_roll_pitch_joint" type="revolute">
        <parent link="head_roll_link" />
        <child link="head_pitch_link" />
        <origin xyz="0 0 0" rpy="0 0 0" />
        <axis xyz="1 0 0" />
        <limit lower="-2.617993878" upper="2.617993878" effort="100" velocity="100" />
    </joint>

    <joint name="head_pitch_head_joint" type="fixed">
        <parent link="head_pitch_link" />
        <child link="head_link" />
        <origin xyz="0 0 0" rpy="0 0 0" />
    </joint>
   

    <joint name="body_power_joint" type="fixed">
        <parent link="body_link" />
        <child link="power_link" />
        <origin xyz="0 0 .190" rpy="0 0 0" />
    </joint>    
    
    <joint name="body_volume_up_joint" type="fixed">
        <parent link="body_link" />
        <child link="volume_up_link" />
        <origin xyz="0 0 .190" rpy="0 0 0" />
    </joint>    
    
    <joint name="body_volume_down_joint" type="fixed">
        <parent link="body_link" />
        <child link="volume_down_link" />
        <origin xyz="0 0 .190" rpy="0 0 0" />
    </joint>
    
    <joint name="head_mouth_joint" type="fixed">
        <parent link="head_link" />
        <child link="mouth_link" />
        <origin xyz="0 0 0" rpy="0 0 0" />
    </joint>

    <joint name="head_left_eye_joint" type="fixed">
        <parent link="head_link" />
        <child link="left_eye_link" />
        <origin xyz="0 0 0" rpy="0 0 0" />
    </joint>

    <joint name="head_right_eye_joint" type="fixed">
        <parent link="head_link" />
        <child link="right_eye_link" />
        <origin xyz="0 0 0" rpy="0 0 0" />
    </joint>

    <joint name="body_left_shoulder_joint" type="revolute">
        <parent link="body_link" />
        <child link="left_shoulder_link" />
        <origin xyz=".039 0 .1415" rpy="0 0 0" />
        <axis xyz="1 0 0" />
        <limit lower="-2.617993878" upper="1.745329252" effort="100" velocity="100" />
    </joint>

    <joint name="left_shoulder_arm_joint" type="revolute">
        <parent link="left_shoulder_link" />
        <child link="left_arm_link" />
        <origin xyz=".0225 -.03897 0" rpy="0 0 0" />
        <axis xyz="0.6258053 .329192519 0.707106769 " />
        <limit lower="-1.745329252" upper="1.221730476" effort="100" velocity="100" />
    </joint>

    <joint name="body_right_shoulder_joint" type="revolute">
        <parent link="body_link" />
        <child link="right_shoulder_link" />
        <origin xyz="-.039 0 .1415" rpy="0 0 0" />
        <axis xyz="1 0 0" />
        <limit lower="-1.745329252" upper="2.617993878" effort="100" velocity="100" />
    </joint>

    <joint name="right_shoulder_arm_joint" type="revolute">
        <parent link="right_shoulder_link" />
        <child link="right_arm_link" />
        <origin xyz="-.0225 -.03897 0" rpy="0 0 0" />
        <axis xyz="-0.6258053 .329192519 0.707106769 " />
        <limit lower="-1.221730476" upper="1.745329252" effort="100" velocity="100" />
    </joint>

</robot>